Workbook

Sheet Inputs
A1: Key | B1: Input | C1: Value | D1: Unit | E1: Tag | F1: Source / note | G1: Link
A2: inc | B2: US PD diagnoses per year (FY2024) | C2: 90000 | D2: patients | E2: A1 | F2: Parkinson's Foundation | G2: https://www.parkinson.org/understanding-parkinsons/statistics/prevalence-incidence
A3: mr | B3: Mortality ratio vs general population | C3: 1.52 | D3: x | E3: A5 | F3: Macleod 2014 | G3: https://doi.org/10.1002/mds.25898
A4: demo | B4: Dementia at 10 yrs, diagnosis age ≥65 | C4: 0.46 | D4: share | E4: A6 | F4: CamPaIGN, Williams-Gray 2013 | G4: https://doi.org/10.1136/jnnp-2013-305277
A5: demy | B5: Dementia among 15-yr survivors, diagnosis age <65 | C5: 0.48 | D5: share | E5: A15 | F5: Sydney, Hely 2005 | G5: https://doi.org/10.1002/mds.20324
A6: mc5 | B6: Motor fluctuations by 4–6 yrs levodopa | C6: 0.4 | D6: share | E6: A7 | F6: Ahlskog & Muenter 2001 | G6: https://doi.org/10.1002/mds.1090
A7: mc15 | B7: Motor complications at 15 yrs | C7: 0.95 | D7: share | E7: A15 | F7: Hely 2005 | G7: https://doi.org/10.1002/mds.20324
A8: dx | B8: Levodopa-responsive idiopathic PD | C8: 0.806 | D8: share | E8: A9 | F8: Rizzo 2016 | G8: https://doi.org/10.1212/WNL.0000000000002350
A9: dur | B9: Minimum disease duration | C9: 4 | D9: years | E9: A | F9: Medtronic label, P960009/S478 | G9: https://www.accessdata.fda.gov/cdrh_docs/pdf/P960009S478B.pdf
A10: dis | B10: Not adequately controlled share of motor complications (shape only) | C10: 0.7 | D10: share | E10: S1 ★ | F10: Sets cohort shape; level is set by eligibility scenario
A11: fit | B11: Medically fit (shape only) | C11: 0.9 | D11: share | E11: S2 ★ | F11: As above
A12: cap | B12: Upper age cap | C12: 75 | D12: years | E12: S3 ★ | F12: Label has no cap; practice ~70–75
A13: dbs | B13: PD DBS per year, 2019 | C13: 3990 | D13: procedures | E13: A10 | F13: NIS 2019 weighted inpatient discharges, PD diagnosis, all ages (Venkatraman 2024, Table 1) | G13: https://pmc.ncbi.nlm.nih.gov/articles/PMC10898494/
A14: dbsu | B14: DBS share under the age cap | C14: 0.85 | D14: share | E14: S5 ★ | F14: Range 75–95%; outpatient uplift tested via this cell (4.5k ⇒ 1.128)
A15: caly | B15: Calibration year | C15: 2019 | D15: FY | E15: A10 | F15: Year of the DBS count
A16: kf | B16: Backlog draw-down per year after launch | C16: 0.5 | D16: share | E16: S6 ★ | F16: Range 25–100%
A17: launch | B17: First one-time therapy launch | C17: 2029 | D17: FY | E17: S7 ★
A18: price | B18: Revenue per procedure | C18: 0.02 | D18: US$M | E18: P | F18: David May: $20k
A19: r | B19: Referral / evaluation (judgment, comparison only) | C19: 0.55 | D19: share | E19: S9 ★ | F19: Range 30–80% (Part 3 notes)
A20: w | B20: Willing among referred (judgment, comparison only) | C20: 0.6 | D20: share | E20: S10 ★ | F20: Range 40–85%; 35–43% published is consent-to-referral (A11, A12); 58.7% of fully evaluated implanted (A21) | G20: https://pmc.ncbi.nlm.nih.gov/articles/PMC6183455/
A21: c | B21: Covered (judgment, comparison only) | C21: 0.9 | D21: share | E21: S4 ★ | F21: Range 80–95%
A22: olm | B22: Ever-DBS share of incident PD, Olmsted County | C22: 0.048 | D22: share | E22: A8 | F22: 16% fluctuations × 29% DBS (Stang 2021, AAN abstract); product is a calculation | G22: https://doi.org/10.1212/WNL.96.15_supplement.4377
B24: Derived (live)
A25: du | B25: DBS under cap per year | C25: =Inputs!$C$13*Inputs!$C$14 | E25: C
A26: spub | B26: Published-screen eligible share of PD, FY2026 | C26: =Cohort!B28/Cohort!H28 | E26: C
A27: Ncal | B27: Published-screen newly eligible in calibration year | C27: =INDEX(Cohort!C:C,MATCH(Inputs!$C$15,Cohort!A:A,0)) | E27: C
A28: LFpub | B28: Lifetime fraction ever eligible, published screens | C28: 0.088249629 | E28: C (cohort)
A29: YE | B29: Mean years eligible per entrant | C29: 6.0980974 | E29: C (cohort)
A30: YD | B30: Mean survival from diagnosis (yrs) | C30: 11.960268 | E30: C (cohort)
A31: rwc | B31: Judgment product r×w×c | C31: =Inputs!$C$19*Inputs!$C$20*Inputs!$C$21 | E31: C
A32: E2000 | B32: Published-screen eligible stock FY2000 | C32: 20423.051 | E32: C
A33: G | B33: Incidence growth (Census 2020–24, age-weighted) | C33: 0.025722148 | E33: C1
B35: Other published inputs used in the cohort model
B36: Hirsch 2016 incidence /100k, age 40s (F, M) | C36: 3.26 | D36: 3.57 | E36: A3 | G36: https://doi.org/10.1159/000445751
B37: Hirsch 2016 incidence /100k, age 50s (F, M) | C37: 10.32 | D37: 12.58 | E37: A3 | G37: https://doi.org/10.1159/000445751
B38: Hirsch 2016 incidence /100k, age 60s (F, M) | C38: 30.32 | D38: 58.22 | E38: A3 | G38: https://doi.org/10.1159/000445751
B39: Hirsch 2016 incidence /100k, age 70s (F, M) | C39: 93.32 | D39: 162.58 | E39: A3 | G39: https://doi.org/10.1159/000445751
B40: Hirsch 2016 incidence /100k, age 80s (F, M) | C40: 103.48 | D40: 258.47 | E40: A3 | G40: https://doi.org/10.1159/000445751
B41: SSA 2023 qx, age 40 | C41: 0.00238 | E41: A4 | G41: https://www.ssa.gov/oact/STATS/table4c6.html
B42: SSA 2023 qx, age 45 | C42: 0.00306 | E42: A4 | G42: https://www.ssa.gov/oact/STATS/table4c6.html
...

Sheet Summary
A1: Class demand for a one-time therapy, patients ('A' DBS keeps volume / 'B' replaces DBS) and $M at $20k
A2: Case | B2: Measure | C2: FY2029 | D2: FY2030 | E2: FY2032 | F2: FY2035 | G2: FY2040 | H2: FY2045
A3: 5% | B3: A: one-time | C3: ='Flow 5%'!K32 | D3: ='Flow 5%'!K33 | E3: ='Flow 5%'!K35 | F3: ='Flow 5%'!K38 | G3: ='Flow 5%'!K43 | H3: ='Flow 5%'!K48
A4: 5% | B4: B: one-time | C4: ='Flow 5%'!P32 | D4: ='Flow 5%'!P33 | E4: ='Flow 5%'!P35 | F4: ='Flow 5%'!P38 | G4: ='Flow 5%'!P43 | H4: ='Flow 5%'!P48
A5: 5% | B5: A: $M | C5: ='Flow 5%'!M32 | D5: ='Flow 5%'!M33 | E5: ='Flow 5%'!M35 | F5: ='Flow 5%'!M38 | G5: ='Flow 5%'!M43 | H5: ='Flow 5%'!M48
A6: 5% | B6: B: $M | C6: ='Flow 5%'!R32 | D6: ='Flow 5%'!R33 | E6: ='Flow 5%'!R35 | F6: ='Flow 5%'!R38 | G6: ='Flow 5%'!R43 | H6: ='Flow 5%'!R48
A7: 8% | B7: A: one-time | C7: ='Flow 8%'!K32 | D7: ='Flow 8%'!K33 | E7: ='Flow 8%'!K35 | F7: ='Flow 8%'!K38 | G7: ='Flow 8%'!K43 | H7: ='Flow 8%'!K48
A8: 8% | B8: B: one-time | C8: ='Flow 8%'!P32 | D8: ='Flow 8%'!P33 | E8: ='Flow 8%'!P35 | F8: ='Flow 8%'!P38 | G8: ='Flow 8%'!P43 | H8: ='Flow 8%'!P48
A9: 8% | B9: A: $M | C9: ='Flow 8%'!M32 | D9: ='Flow 8%'!M33 | E9: ='Flow 8%'!M35 | F9: ='Flow 8%'!M38 | G9: ='Flow 8%'!M43 | H9: ='Flow 8%'!M48
A10: 8% | B10: B: $M | C10: ='Flow 8%'!R32 | D10: ='Flow 8%'!R33 | E10: ='Flow 8%'!R35 | F10: ='Flow 8%'!R38 | G10: ='Flow 8%'!R43 | H10: ='Flow 8%'!R48
A11: 10% | B11: A: one-time | C11: ='Flow 10%'!K32 | D11: ='Flow 10%'!K33 | E11: ='Flow 10%'!K35 | F11: ='Flow 10%'!K38 | G11: ='Flow 10%'!K43 | H11: ='Flow 10%'!K48
A12: 10% | B12: B: one-time | C12: ='Flow 10%'!P32 | D12: ='Flow 10%'!P33 | E12: ='Flow 10%'!P35 | F12: ='Flow 10%'!P38 | G12: ='Flow 10%'!P43 | H12: ='Flow 10%'!P48
A13: 10% | B13: A: $M | C13: ='Flow 10%'!M32 | D13: ='Flow 10%'!M33 | E13: ='Flow 10%'!M35 | F13: ='Flow 10%'!M38 | G13: ='Flow 10%'!M43 | H13: ='Flow 10%'!M48
A14: 10% | B14: B: $M | C14: ='Flow 10%'!R32 | D14: ='Flow 10%'!R33 | E14: ='Flow 10%'!R35 | F14: ='Flow 10%'!R38 | G14: ='Flow 10%'!R43 | H14: ='Flow 10%'!R48
A15: 15% | B15: A: one-time | C15: ='Flow 15%'!K32 | D15: ='Flow 15%'!K33 | E15: ='Flow 15%'!K35 | F15: ='Flow 15%'!K38 | G15: ='Flow 15%'!K43 | H15: ='Flow 15%'!K48
A16: 15% | B16: B: one-time | C16: ='Flow 15%'!P32 | D16: ='Flow 15%'!P33 | E16: ='Flow 15%'!P35 | F16: ='Flow 15%'!P38 | G16: ='Flow 15%'!P43 | H16: ='Flow 15%'!P48
A17: 15% | B17: A: $M | C17: ='Flow 15%'!M32 | D17: ='Flow 15%'!M33 | E17: ='Flow 15%'!M35 | F17: ='Flow 15%'!M38 | G17: ='Flow 15%'!M43 | H17: ='Flow 15%'!M48
A18: 15% | B18: B: $M | C18: ='Flow 15%'!R32 | D18: ='Flow 15%'!R33 | E18: ='Flow 15%'!R35 | F18: ='Flow 15%'!R38 | G18: ='Flow 15%'!R43 | H18: ='Flow 15%'!R48
A20: Convergence (central 8%)
B21: FY2045 funnel inflow = newly eligible × P (B demand → this as kf → 1) | C21: ='Flow 8%'!H48
B22: FY2045 B demand at base kf | C22: ='Flow 8%'!P48
B23: Ratio | C23: =C22/C21
B24: kf=1 run, FY2045 B demand (from pd_pool_model.py; set Inputs kf=1 to reproduce live) | C24: 6563.9443

Sheet Cohort
A1: Published-screen cohort (pd_pool_model.py). Eligible = alive, no dementia, under cap, ≥4 yrs, with motor complications × dx × S1 × S2.
A2: FY | B2: Eligible stock (published screens) | C2: Newly eligible | D2: Exit rate μ | E2: Deaths | F2: Dementia | G2: Aged past cap | H2: PD prevalent | I2: PD incidence
A3: 2001 | B3: 20948.376 | C3: 3834.062 | D3: 0.16200994 | E3: 524.95867 | F3: 795.62956 | G3: 1988.1491 | H3: 489074.48 | I3: 50183.234
A4: 2002 | B4: 21487.213 | C4: 3932.6824 | D4: 0.16200994 | E4: 538.46173 | F4: 816.09486 | G4: 2039.2885 | H4: 501654.52 | I4: 51474.054
A5: 2003 | B5: 22039.91 | C5: 4033.8394 | D5: 0.16200994 | E5: 552.31212 | F5: 837.08658 | G5: 2091.7434 | H5: 514558.15 | I5: 52798.078
A6: 2004 | B6: 22606.824 | C6: 4137.5984 | D6: 0.16200994 | E6: 566.51878 | F6: 858.61824 | G6: 2145.5476 | H6: 527793.7 | I6: 54156.158
A7: 2005 | B7: 23188.32 | C7: 4244.0263 | D7: 0.16200994 | E7: 581.09086 | F7: 880.70375 | G7: 2200.7356 | H7: 541369.68 | I7: 55549.17
A8: 2006 | B8: 23784.774 | C8: 4353.1918 | D8: 0.16200994 | E8: 596.03776 | F8: 903.35734 | G8: 2257.3433 | H8: 555294.87 | I8: 56978.014
A9: 2007 | B9: 24396.569 | C9: 4465.1653 | D9: 0.16200994 | E9: 611.36913 | F9: 926.59363 | G9: 2315.407 | H9: 569578.25 | I9: 58443.611
A10: 2008 | B10: 25024.101 | C10: 4580.0189 | D10: 0.16200994 | E10: 627.09486 | F10: 950.42761 | G10: 2374.9643 | H10: 584229.03 | I10: 59946.906
A11: 2009 | B11: 25667.775 | C11: 4697.8268 | D11: 0.16200994 | E11: 643.22509 | F11: 974.87465 | G11: 2436.0534 | H11: 599256.65 | I11: 61488.87
A12: 2010 | B12: 26328.005 | C12: 4818.665 | D12: 0.16200994 | E12: 659.77022 | F12: 999.95052 | G12: 2498.714 | H12: 614670.82 | I12: 63070.496
A13: 2011 | B13: 27005.218 | C13: 4942.6114 | D13: 0.16200994 | E13: 676.74093 | F13: 1025.6714 | G13: 2562.9863 | H13: 630481.48 | I13: 64692.804
A14: 2012 | B14: 27699.85 | C14: 5069.746 | D14: 0.16200994 | E14: 694.14816 | F14: 1052.0539 | G14: 2628.9118 | H14: 646698.81 | I14: 66356.842
... A47: 2045 | B47: 64041.076 | C47: 11721.074 | D47: 0.16200994 | E47: 1604.846 | F47: 2432.3114 | G47: 6077.9512 | H47: 1495144.8 | I47: 153414.68

Sheet Scenarios
A1: Eligibility scenarios (point prevalence of US PD meeting label-style criteria, cap 75). Product P = r×w×c is calibrated so DBS under cap = FY2019 volume. Central = 8% (★).
A2: Row | B2: Measure | C2: Case 5% | D2: Case 8% | E2: Case 10% | F2: Case 15% | G2: Note
A3: 3 | B3: Eligible, point prevalence (input) | C3: 0.05 | D3: 0.08 | E3: 0.1 | F3: 0.15
A4: 4 | B4: Scale on published screens g | C4: =C3/Inputs!$C$26 | D4: =D3/Inputs!$C$26 | E4: =E3/Inputs!$C$26 | F4: =F3/Inputs!$C$26
A5: 5 | B5: Calibrated product P = r×w×c | C5: =Inputs!$C$25/(C4*Inputs!$C$27) | D5: =Inputs!$C$25/(D4*Inputs!$C$27) | E5: =Inputs!$C$25/(E4*Inputs!$C$27) | F5: =Inputs!$C$25/(F4*Inputs!$C$27) | G5: Only calibrated quantity
A6: 6 | B6: Lifetime fraction ever eligible | C6: =Inputs!$C$28*C4 | D6: =Inputs!$C$28*D4 | E6: =Inputs!$C$28*E4 | F6: =Inputs!$C$28*F4
A7: 7 | B7: Implied s ≈ LF × YE / YD (check) | C7: =C6*Inputs!$C$29/Inputs!$C$30 | D7: =D6*Inputs!$C$29/Inputs!$C$30 | E7: =E6*Inputs!$C$29/Inputs!$C$30 | F7: =F6*Inputs!$C$29/Inputs!$C$30 | G7: Differs from row 3 by growth and age mix
A8: 8 | B8: Eligible stock FY2026 | C8: =C4*Cohort!B28 | D8: =D4*Cohort!B28 | E8: =E4*Cohort!B28 | F8: =F4*Cohort!B28
A9: 9 | B9: Newly eligible FY2026 | C9: =C4*Cohort!C28 | D9: =D4*Cohort!C28 | E9: =E4*Cohort!C28 | F9: =F4*Cohort!C28
A10: 10 | B10: Olmsted-implied lifetime eligible = 4.8% ÷ P | C10: =Inputs!$C$22/C5 | D10: =Inputs!$C$22/D5 | E10: =Inputs!$C$22/E5 | F10: =Inputs!$C$22/F5
A11: 11 | B11: Model ever-DBS share of incidence = LF × P | C11: =C6*C5 | D11: =D6*D5 | E11: =E6*E5 | F11: =F6*F5 | G11: Same for every case: it is pinned by DBS volume ÷ incidence
A12: 12 | B12: Judgment product r×w×c | C12: =Inputs!$C$31 | D12: =Inputs!$C$31 | E12: =Inputs!$C$31 | F12: =Inputs!$C$31
A13: 13 | B13: DBS FY2019 implied at judgment product | C13: =Inputs!$C$31*C4*Inputs!$C$27 | D13: =Inputs!$C$31*D4*Inputs!$C$27 | E13: =Inputs!$C$31*E4*Inputs!$C$27 | F13: =Inputs!$C$31*F4*Inputs!$C$27
A14: 14 | B14: Plausibility (P within 0.10–0.65; central 0.30) | C14: =IF(OR(C5>0.65,C5<0.1),"implausible",IF(OR(C5>0.45,C5<0.18),"edge of range","plausible")) | D14: =IF(OR(D5>0.65,D5<0.1),"implausible",IF(OR(D5>0.45,D5<0.18),"edge of range","plausible")) | E14: =IF(OR(E5>0.65,E5<0.1),"implausible",IF(OR(E5>0.45,E5<0.18),"edge of range","plausible")) | F14: =IF(OR(F5>0.65,F5<0.1),"implausible",IF(OR(F5>0.45,F5<0.18),"edge of range","plausible"))

Sheet Flow 5%
A1: Eligibility case 5%. Eligible = Cohort × g; funnel inflow = newly eligible × P. Pre-launch DBS = MIN(DBS under cap, pool). After launch: A keeps DBS and the one-time therapy draws kf of the backlog; B replaces DBS (DBS-equivalent volume + kf of backlog). Rows before FY2026 grouped.
A2: FY | B2: Eligible stock | C2: Newly eligible | D2: Exit μ | E2: Deaths | F2: Dementia | G2: Aged past cap | H2: Funnel inflow (×P) | I2: A: pool available | J2: A: DBS | K2: A: one-time | L2: A: backlog end | M2: A: $M | N2: B: pool available | O2: B: DBS | P2: B: one-time | Q2: B: backlog end | R2: B: $M | S2: PD prevalent | T2: Eligible % of PD
A3: 2000 | L3: 0 | Q3: 0
A4: 2001 | B4: =Cohort!B3*Scenarios!$C$4 | C4: =Cohort!C3*Scenarios!$C$4 | D4: =Cohort!D3 | E4: =Cohort!E3*Scenarios!$C$4 | F4: =Cohort!F3*Scenarios!$C$4 | G4: =Cohort!G3*Scenarios!$C$4 | H4: =C4*Scenarios!$C$5 | I4: =L3*(1-D4)+H4 | J4: =MIN(Inputs!$C$25,I4) | K4: =IF(A4<Inputs!$C$17,0,Inputs!$C$16*(I4-J4)) | L4: =I4-J4-K4 | M4: =K4*Inputs!$C$18 | N4: =Q3*(1-D4)+H4 | O4: =IF(A4<Inputs!$C$17,MIN(Inputs!$C$25,N4),0) | P4: =IF(A4<Inputs!$C$17,0,MIN(Inputs!$C$25,N4)+Inputs!$C$16*(N4-MIN(Inputs!$C$25,N4))) | Q4: =N4-O4-P4 | R4: =P4*Inputs!$C$18 | S4: =Cohort!H3 | T4: =B4/S4
A5: 2002 | B5: =Cohort!B4*Scenarios!$C$4 | C5: =Cohort!C4*Scenarios!$C$4 | D5: =Cohort!D4 | E5: =Cohort!E4*Scenarios!$C$4 | F5: =Cohort!F4*Scenarios!$C$4 | G5: =Cohort!G4*Scenarios!$C$4 | H5: =C5*Scenarios!$C$5 | I5: =L4*(1-D5)+H5 | J5: =MIN(Inputs!$C$25,I5) | K5: =IF(A5<Inputs!$C$17,0,Inputs!$C$16*(I5-J5)) | L5: =I5-J5-K5 | M5: =K5*Inputs!$C$18 | N5: =Q4*(1-D5)+H5 | O5: =IF(A5<Inputs!$C$17,MIN(Inputs!$C$25,N5),0) | P5: =IF(A5<Inputs!$C$17,0,MIN(Inputs!$C$25,N5)+Inputs!$C$16*(N5-MIN(Inputs!$C$25,N5))) | Q5: =N5-O5-P5 | R5: =P5*Inputs!$C$18 | S5: =Cohort!H4 | T5: =B5/S5
A6: 2003 | B6: =Cohort!B5*Scenarios!$C$4 | C6: =Cohort!C5*Scenarios!$C$4 | D6: =Cohort!D5 | E6: =Cohort!E5*Scenarios!$C$4 | F6: =Cohort!F5*Scenarios!$C$4 | G6: =Cohort!G5*Scenarios!$C$4 | H6: =C6*Scenarios!$C$5 | I6: =L5*(1-D6)+H6 | J6: =MIN(Inputs!$C$25,I6) | K6: =IF(A6<Inputs!$C$17,0,Inputs!$C$16*(I6-J6)) | L6: =I6-J6-K6 | M6: =K6*Inputs!$C$18 | N6: =Q5*(1-D6)+H6 | O6: =IF(A6<Inputs!$C$17,MIN(Inputs!$C$25,N6),0) | P6: =IF(A6<Inputs!$C$17,0,MIN(Inputs!$C$25,N6)+Inputs!$C$16*(N6-MIN(Inputs!$C$25,N6))) | Q6: =N6-O6-P6 | R6: =P6*Inputs!$C$18 | S6: =Cohort!H5 | T6: =B6/S6
A7: 2004 | B7: =Cohort!B6*Scenarios!$C$4 | C7: =Cohort!C6*Scenarios!$C$4 | D7: =Cohort!D6 | E7: =Cohort!E6*Scenarios!$C$4 | F7: =Cohort!F6*Scenarios!$C$4 | G7: =Cohort!G6*Scenarios!$C$4 | H7: =C7*Scenarios!$C$5 | I7: =L6*(1-D7)+H7 | J7: =MIN(Inputs!$C$25,I7) | K7: =IF(A7<Inputs!$C$17,0,Inputs!$C$16*(I7-J7)) | L7: =I7-J7-K7 | M7: =K7*Inputs!$C$18 | N7: =Q6*(1-D7)+H7 | O7: =IF(A7<Inputs!$C$17,MIN(Inputs!$C$25,N7),0) | P7: =IF(A7<Inputs!$C$17,0,MIN(Inputs!$C$25,N7)+Inputs!$C$16*(N7-MIN(Inputs!$C$25,N7))) | Q7: =N7-O7-P7 | R7: =P7*Inputs!$C$18 | S7: =Cohort!H6 | T7: =B7/S7
A8: 2005 | B8: =Cohort!B7*Scenarios!$C$4 | C8: =Cohort!C7*Scenarios!$C$4 | D8: =Cohort!D7 | E8: =Cohort!E7*Scenarios!$C$4 | F8: =Cohort!F7*Scenarios!$C$4 | G8: =Cohort!G7*Scenarios!$C$4 | H8: =C8*Scenarios!$C$5 | I8: =L7*(1-D8)+H8 | J8: =MIN(Inputs!$C$25,I8) | K8: =IF(A8<Inputs!$C$17,0,Inputs!$C$16*(I8-J8)) | L8: =I8-J8-K8 | M8: =K8*Inputs!$C$18 | N8: =Q7*(1-D8)+H8 | O8: =IF(A8<Inputs!$C$17,MIN(Inputs!$C$25,N8),0) | P8: =IF(A8<Inputs!$C$17,0,MIN(Inputs!$C$25,N8)+Inputs!$C$16*(N8-MIN(Inputs!$C$25,N8))) | Q8: =N8-O8-P8 | R8: =P8*Inputs!$C$18 | S8: =Cohort!H7 | T8: =B8/S8
A9: 2006 | B9: =Cohort!B8*Scenarios!$C$4 | C9: =Cohort!C8*Scenarios!$C$4 | D9: =Cohort!D8 | E9: =Cohort!E8*Scenarios!$C$4 | F9: =Cohort!F8*Scenarios!$C$4 | G9: =Cohort!G8*Scenarios!$C$4 | H9: =C9*Scenarios!$C$5 | I9: =L8*(1-D9)+H9 | J9: =MIN(Inputs!$C$25,I9) | K9: =IF(A9<Inputs!$C$17,0,Inputs!$C$16*(I9-J9)) | L9: =I9-J9-K9 | M9: =K9*Inputs!$C$18 | N9: =Q8*(1-D9)+H9 | O9: =IF(A9<Inputs!$C$17,MIN(Inputs!$C$25,N9),0) | P9: =IF(A9<Inputs!$C$17,0,MIN(Inputs!$C$25,N9)+Inputs!$C$16*(N9-MIN(Inputs!$C$25,N9))) | Q9: =N9-O9-P9 | R9: =P9*Inputs!$C$18 | S9: =Cohort!H8 | T9: =B9/S9
A10: 2007 | B10: =Cohort!B9*Scenarios!$C$4 | C10: =Cohort!C9*Scenarios!$C$4 | D10: =Cohort!D9 | E10: =Cohort!E9*Scenarios!$C$4 | F10: =Cohort!F9*Scenarios!$C$4 | G10: =Cohort!G9*Scenarios!$C$4 | H10: =C10*Scenarios!$C$5 | I10: =L9*(1-D10)+H10 | J10: =MIN(Inputs!$C$25,I10) | K10: =IF(A10<Inputs!$C$17,0,Inputs!$C$16*(I10-J10)) | L10: =I10-J10-K10 | M10: =K10*Inputs!$C$18 | N10: =Q9*(1-D10)+H10 | O10: =IF(A10<Inputs!$C$17,MIN(Inputs!$C$25,N10),0) | P10: =IF(A10<Inputs!$C$17,0,MIN(Inputs!$C$25,N10)+Inputs!$C$16*(N10-MIN(Inputs!$C$25,N10))) | Q10: =N10-O10-P10 | R10: =P10*Inputs!$C$18 | S10: =Cohort!H9 | T10: =B10/S10
A11: 2008 | B11: =Cohort!B10*Scenarios!$C$4 | C11: =Cohort!C10*Scenarios!$C$4 | D11: =Cohort!D10 | E11: =Cohort!E10*Scenarios!$C$4 | F11: =Cohort!F10*Scenarios!$C$4 | G11: =Cohort!G10*Scenarios!$C$4 | H11: =C11*Scenarios!$C$5 | I11: =L10*(1-D11)+H11 | J11: =MIN(Inputs!$C$25,I11) | K11: =IF(A11<Inputs!$C$17,0,Inputs!$C$16*(I11-J11)) | L11: =I11-J11-K11 | M11: =K11*Inputs!$C$18 | N11: =Q10*(1-D11)+H11 | O11: =IF(A11<Inputs!$C$17,MIN(Inputs!$C$25,N11),0) | P11: =IF(A11<Inputs!$C$17,0,MIN(Inputs!$C$25,N11)+Inputs!$C$16*(N11-MIN(Inputs!$C$25,N11))) | Q11: =N11-O11-P11 | R11: =P11*Inputs!$C$18 | S11: =Cohort!H10 | T11: =B11/S11
A12: 2009 | B12: =Cohort!B11*Scenarios!$C$4 | C12: =Cohort!C11*Scenarios!$C$4 | D12: =Cohort!D11 | E12: =Cohort!E11*Scenarios!$C$4 | F12: =Cohort!F11*Scenarios!$C$4 | G12: =Cohort!G11*Scenarios!$C$4 | H12: =C12*Scenarios!$C$5 | I12: =L11*(1-D12)+H12 | J12: =MIN(Inputs!$C$25,I12) | K12: =IF(A12<Inputs!$C$17,0,Inputs!$C$16*(I12-J12)) | L12: =I12-J12-K12 | M12: =K12*Inputs!$C$18 | N12: =Q11*(1-D12)+H12 | O12: =IF(A12<Inputs!$C$17,MIN(Inputs!$C$25,N12),0) | P12: =IF(A12<Inputs!$C$17,0,MIN(Inputs!$C$25,N12)+Inputs!$C$16*(N12-MIN(Inputs!$C$25,N12))) | Q12: =N12-O12-P12 | R12: =P12*Inputs!$C$18 | S12: =Cohort!H11 | T12: =B12/S12
A13: 2010 | B13: =Cohort!B12*Scenarios!$C$4 | C13: =Cohort!C12*Scenarios!$C$4 | D13: =Cohort!D12 | E13: =Cohort!E12*Scenarios!$C$4 | F13: =Cohort!F12*Scenarios!$C$4 | G13: =Cohort!G12*Scenarios!$C$4 | H13: =C13*Scenarios!$C$5 | I13: =L12*(1-D13)+H13 | J13: =MIN(Inputs!$C$25,I13) | K13: =IF(A13<Inputs!$C$17,0,Inputs!$C$16*(I13-J13)) | L13: =I13-J13-K13 | M13: =K13*Inputs!$C$18 | N13: =Q12*(1-D13)+H13 | O13: =IF(A13<Inputs!$C$17,MIN(Inputs!$C$25,N13),0) | P13: =IF(A13<Inputs!$C$17,0,MIN(Inputs!$C$25,N13)+Inputs!$C$16*(N13-MIN(Inputs!$C$25,N13))) | Q13: =N13-O13-P13 | R13: =P13*Inputs!$C$18 | S13: =Cohort!H12 | T13: =B13/S13
A14: 2011 | B14: =Cohort!B13*Scenarios!$C$4 | C14: =Cohort!C13*Scenarios!$C$4 | D14: =Cohort!D13 | E14: =Cohort!E13*Scenarios!$C$4 | F14: =Cohort!F13*Scenarios!$C$4 | G14: =Cohort!G13*Scenarios!$C$4 | H14: =C14*Scenarios!$C$5 | I14: =L13*(1-D14)+H14 | J14: =MIN(Inputs!$C$25,I14) | K14: =IF(A14<Inputs!$C$17,0,Inputs!$C$16*(I14-J14)) | L14: =I14-J14-K14 | M14: =K14*Inputs!$C$18 | N14: =Q13*(1-D14)+H14 | O14: =IF(A14<Inputs!$C$17,MIN(Inputs!$C$25,N14),0) | P14: =IF(A14<Inputs!$C$17,0,MIN(Inputs!$C$25,N14)+Inputs!$C$16*(N14-MIN(Inputs!$C$25,N14))) | Q14: =N14-O14-P14 | R14: =P14*Inputs!$C$18 | S14: =Cohort!H13 | T14: =B14/S14
A15: 2012 | B15: =Cohort!B14*Scenarios!$C$4 | C15: =Cohort!C14*Scenarios!$C$4 | D15: =Cohort!D14 | E15: =Cohort!E14*Scenarios!$C$4 | F15: =Cohort!F14*Scenarios!$C$4 | G15: =Cohort!G14*Scenarios!$C$4 | H15: =C15*Scenarios!$C$5 | I15: =L14*(1-D15)+H15 | J15: =MIN(Inputs!$C$25,I15) | K15: =IF(A15<Inputs!$C$17,0,Inputs!$C$16*(I15-J15)) | L15: =I15-J15-K15 | M15: =K15*Inputs!$C$18 | N15: =Q14*(1-D15)+H15 | O15: =IF(A15<Inputs!$C$17,MIN(Inputs!$C$25,N15),0) | P15: =IF(A15<Inputs!$C$17,0,MIN(Inputs!$C$25,N15)+Inputs!$C$16*(N15-MIN(Inputs!$C$25,N15))) | Q15: =N15-O15-P15 | R15: =P15*Inputs!$C$18 | S15: =Cohort!H14 | T15: =B15/S15
... A48: 2045 | B48: =Cohort!B47*Scenarios!$C$4 | C48: =Cohort!C47*Scenarios!$C$4 | D48: =Cohort!D47 | E48: =Cohort!E47*Scenarios!$C$4 | F48: =Cohort!F47*Scenarios!$C$4 | G48: =Cohort!G47*Scenarios!$C$4 | H48: =C48*Scenarios!$C$5 | I48: =L47*(1-D48)+H48 | J48: =MIN(Inputs!$C$25,I48) | K48: =IF(A48<Inputs!$C$17,0,Inputs!$C$16*(I48-J48)) | L48: =I48-J48-K48 | M48: =K48*Inputs!$C$18 | N48: =Q47*(1-D48)+H48 | O48: =IF(A48<Inputs!$C$17,MIN(Inputs!$C$25,N48),0) | P48: =IF(A48<Inputs!$C$17,0,MIN(Inputs!$C$25,N48)+Inputs!$C$16*(N48-MIN(Inputs!$C$25,N48))) | Q48: =N48-O48-P48 | R48: =P48*Inputs!$C$18 | S48: =Cohort!H47 | T48: =B48/S48

Sheet Flow 8%
A1: Eligibility case 8%. Eligible = Cohort × g; funnel inflow = newly eligible × P. Pre-launch DBS = MIN(DBS under cap, pool). After launch: A keeps DBS and the one-time therapy draws kf of the backlog; B replaces DBS (DBS-equivalent volume + kf of backlog). Rows before FY2026 grouped.
A2: FY | B2: Eligible stock | C2: Newly eligible | D2: Exit μ | E2: Deaths | F2: Dementia | G2: Aged past cap | H2: Funnel inflow (×P) | I2: A: pool available | J2: A: DBS | K2: A: one-time | L2: A: backlog end | M2: A: $M | N2: B: pool available | O2: B: DBS | P2: B: one-time | Q2: B: backlog end | R2: B: $M | S2: PD prevalent | T2: Eligible % of PD
A3: 2000 | L3: 0 | Q3: 0
A4: 2001 | B4: =Cohort!B3*Scenarios!$D$4 | C4: =Cohort!C3*Scenarios!$D$4 | D4: =Cohort!D3 | E4: =Cohort!E3*Scenarios!$D$4 | F4: =Cohort!F3*Scenarios!$D$4 | G4: =Cohort!G3*Scenarios!$D$4 | H4: =C4*Scenarios!$D$5 | I4: =L3*(1-D4)+H4 | J4: =MIN(Inputs!$C$25,I4) | K4: =IF(A4<Inputs!$C$17,0,Inputs!$C$16*(I4-J4)) | L4: =I4-J4-K4 | M4: =K4*Inputs!$C$18 | N4: =Q3*(1-D4)+H4 | O4: =IF(A4<Inputs!$C$17,MIN(Inputs!$C$25,N4),0) | P4: =IF(A4<Inputs!$C$17,0,MIN(Inputs!$C$25,N4)+Inputs!$C$16*(N4-MIN(Inputs!$C$25,N4))) | Q4: =N4-O4-P4 | R4: =P4*Inputs!$C$18 | S4: =Cohort!H3 | T4: =B4/S4
A5: 2002 | B5: =Cohort!B4*Scenarios!$D$4 | C5: =Cohort!C4*Scenarios!$D$4 | D5: =Cohort!D4 | E5: =Cohort!E4*Scenarios!$D$4 | F5: =Cohort!F4*Scenarios!$D$4 | G5: =Cohort!G4*Scenarios!$D$4 | H5: =C5*Scenarios!$D$5 | I5: =L4*(1-D5)+H5 | J5: =MIN(Inputs!$C$25,I5) | K5: =IF(A5<Inputs!$C$17,0,Inputs!$C$16*(I5-J5)) | L5: =I5-J5-K5 | M5: =K5*Inputs!$C$18 | N5: =Q4*(1-D5)+H5 | O5: =IF(A5<Inputs!$C$17,MIN(Inputs!$C$25,N5),0) | P5: =IF(A5<Inputs!$C$17,0,MIN(Inputs!$C$25,N5)+Inputs!$C$16*(N5-MIN(Inputs!$C$25,N5))) | Q5: =N5-O5-P5 | R5: =P5*Inputs!$C$18 | S5: =Cohort!H4 | T5: =B5/S5
A6: 2003 | B6: =Cohort!B5*Scenarios!$D$4 | C6: =Cohort!C5*Scenarios!$D$4 | D6: =Cohort!D5 | E6: =Cohort!E5*Scenarios!$D$4 | F6: =Cohort!F5*Scenarios!$D$4 | G6: =Cohort!G5*Scenarios!$D$4 | H6: =C6*Scenarios!$D$5 | I6: =L5*(1-D6)+H6 | J6: =MIN(Inputs!$C$25,I6) | K6: =IF(A6<Inputs!$C$17,0,Inputs!$C$16*(I6-J6)) | L6: =I6-J6-K6 | M6: =K6*Inputs!$C$18 | N6: =Q5*(1-D6)+H6 | O6: =IF(A6<Inputs!$C$17,MIN(Inputs!$C$25,N6),0) | P6: =IF(A6<Inputs!$C$17,0,MIN(Inputs!$C$25,N6)+Inputs!$C$16*(N6-MIN(Inputs!$C$25,N6))) | Q6: =N6-O6-P6 | R6: =P6*Inputs!$C$18 | S6: =Cohort!H5 | T6: =B6/S6
A7: 2004 | B7: =Cohort!B6*Scenarios!$D$4 | C7: =Cohort!C6*Scenarios!$D$4 | D7: =Cohort!D6 | E7: =Cohort!E6*Scenarios!$D$4 | F7: =Cohort!F6*Scenarios!$D$4 | G7: =Cohort!G6*Scenarios!$D$4 | H7: =C7*Scenarios!$D$5 | I7: =L6*(1-D7)+H7 | J7: =MIN(Inputs!$C$25,I7) | K7: =IF(A7<Inputs!$C$17,0,Inputs!$C$16*(I7-J7)) | L7: =I7-J7-K7 | M7: =K7*Inputs!$C$18 | N7: =Q6*(1-D7)+H7 | O7: =IF(A7<Inputs!$C$17,MIN(Inputs!$C$25,N7),0) | P7: =IF(A7<Inputs!$C$17,0,MIN(Inputs!$C$25,N7)+Inputs!$C$16*(N7-MIN(Inputs!$C$25,N7))) | Q7: =N7-O7-P7 | R7: =P7*Inputs!$C$18 | S7: =Cohort!H6 | T7: =B7/S7
A8: 2005 | B8: =Cohort!B7*Scenarios!$D$4 | C8: =Cohort!C7*Scenarios!$D$4 | D8: =Cohort!D7 | E8: =Cohort!E7*Scenarios!$D$4 | F8: =Cohort!F7*Scenarios!$D$4 | G8: =Cohort!G7*Scenarios!$D$4 | H8: =C8*Scenarios!$D$5 | I8: =L7*(1-D8)+H8 | J8: =MIN(Inputs!$C$25,I8) | K8: =IF(A8<Inputs!$C$17,0,Inputs!$C$16*(I8-J8)) | L8: =I8-J8-K8 | M8: =K8*Inputs!$C$18 | N8: =Q7*(1-D8)+H8 | O8: =IF(A8<Inputs!$C$17,MIN(Inputs!$C$25,N8),0) | P8: =IF(A8<Inputs!$C$17,0,MIN(Inputs!$C$25,N8)+Inputs!$C$16*(N8-MIN(Inputs!$C$25,N8))) | Q8: =N8-O8-P8 | R8: =P8*Inputs!$C$18 | S8: =Cohort!H7 | T8: =B8/S8
A9: 2006 | B9: =Cohort!B8*Scenarios!$D$4 | C9: =Cohort!C8*Scenarios!$D$4 | D9: =Cohort!D8 | E9: =Cohort!E8*Scenarios!$D$4 | F9: =Cohort!F8*Scenarios!$D$4 | G9: =Cohort!G8*Scenarios!$D$4 | H9: =C9*Scenarios!$D$5 | I9: =L8*(1-D9)+H9 | J9: =MIN(Inputs!$C$25,I9) | K9: =IF(A9<Inputs!$C$17,0,Inputs!$C$16*(I9-J9)) | L9: =I9-J9-K9 | M9: =K9*Inputs!$C$18 | N9: =Q8*(1-D9)+H9 | O9: =IF(A9<Inputs!$C$17,MIN(Inputs!$C$25,N9),0) | P9: =IF(A9<Inputs!$C$17,0,MIN(Inputs!$C$25,N9)+Inputs!$C$16*(N9-MIN(Inputs!$C$25,N9))) | Q9: =N9-O9-P9 | R9: =P9*Inputs!$C$18 | S9: =Cohort!H8 | T9: =B9/S9
A10: 2007 | B10: =Cohort!B9*Scenarios!$D$4 | C10: =Cohort!C9*Scenarios!$D$4 | D10: =Cohort!D9 | E10: =Cohort!E9*Scenarios!$D$4 | F10: =Cohort!F9*Scenarios!$D$4 | G10: =Cohort!G9*Scenarios!$D$4 | H10: =C10*Scenarios!$D$5 | I10: =L9*(1-D10)+H10 | J10: =MIN(Inputs!$C$25,I10) | K10: =IF(A10<Inputs!$C$17,0,Inputs!$C$16*(I10-J10)) | L10: =I10-J10-K10 | M10: =K10*Inputs!$C$18 | N10: =Q9*(1-D10)+H10 | O10: =IF(A10<Inputs!$C$17,MIN(Inputs!$C$25,N10),0) | P10: =IF(A10<Inputs!$C$17,0,MIN(Inputs!$C$25,N10)+Inputs!$C$16*(N10-MIN(Inputs!$C$25,N10))) | Q10: =N10-O10-P10 | R10: =P10*Inputs!$C$18 | S10: =Cohort!H9 | T10: =B10/S10
A11: 2008 | B11: =Cohort!B10*Scenarios!$D$4 | C11: =Cohort!C10*Scenarios!$D$4 | D11: =Cohort!D10 | E11: =Cohort!E10*Scenarios!$D$4 | F11: =Cohort!F10*Scenarios!$D$4 | G11: =Cohort!G10*Scenarios!$D$4 | H11: =C11*Scenarios!$D$5 | I11: =L10*(1-D11)+H11 | J11: =MIN(Inputs!$C$25,I11) | K11: =IF(A11<Inputs!$C$17,0,Inputs!$C$16*(I11-J11)) | L11: =I11-J11-K11 | M11: =K11*Inputs!$C$18 | N11: =Q10*(1-D11)+H11 | O11: =IF(A11<Inputs!$C$17,MIN(Inputs!$C$25,N11),0) | P11: =IF(A11<Inputs!$C$17,0,MIN(Inputs!$C$25,N11)+Inputs!$C$16*(N11-MIN(Inputs!$C$25,N11))) | Q11: =N11-O11-P11 | R11: =P11*Inputs!$C$18 | S11: =Cohort!H10 | T11: =B11/S11
A12: 2009 | B12: =Cohort!B11*Scenarios!$D$4 | C12: =Cohort!C11*Scenarios!$D$4 | D12: =Cohort!D11 | E12: =Cohort!E11*Scenarios!$D$4 | F12: =Cohort!F11*Scenarios!$D$4 | G12: =Cohort!G11*Scenarios!$D$4 | H12: =C12*Scenarios!$D$5 | I12: =L11*(1-D12)+H12 | J12: =MIN(Inputs!$C$25,I12) | K12: =IF(A12<Inputs!$C$17,0,Inputs!$C$16*(I12-J12)) | L12: =I12-J12-K12 | M12: =K12*Inputs!$C$18 | N12: =Q11*(1-D12)+H12 | O12: =IF(A12<Inputs!$C$17,MIN(Inputs!$C$25,N12),0) | P12: =IF(A12<Inputs!$C$17,0,MIN(Inputs!$C$25,N12)+Inputs!$C$16*(N12-MIN(Inputs!$C$25,N12))) | Q12: =N12-O12-P12 | R12: =P12*Inputs!$C$18 | S12: =Cohort!H11 | T12: =B12/S12
A13: 2010 | B13: =Cohort!B12*Scenarios!$D$4 | C13: =Cohort!C12*Scenarios!$D$4 | D13: =Cohort!D12 | E13: =Cohort!E12*Scenarios!$D$4 | F13: =Cohort!F12*Scenarios!$D$4 | G13: =Cohort!G12*Scenarios!$D$4 | H13: =C13*Scenarios!$D$5 | I13: =L12*(1-D13)+H13 | J13: =MIN(Inputs!$C$25,I13) | K13: =IF(A13<Inputs!$C$17,0,Inputs!$C$16*(I13-J13)) | L13: =I13-J13-K13 | M13: =K13*Inputs!$C$18 | N13: =Q12*(1-D13)+H13 | O13: =IF(A13<Inputs!$C$17,MIN(Inputs!$C$25,N13),0) | P13: =IF(A13<Inputs!$C$17,0,MIN(Inputs!$C$25,N13)+Inputs!$C$16*(N13-MIN(Inputs!$C$25,N13))) | Q13: =N13-O13-P13 | R13: =P13*Inputs!$C$18 | S13: =Cohort!H12 | T13: =B13/S13
A14: 2011 | B14: =Cohort!B13*Scenarios!$D$4 | C14: =Cohort!C13*Scenarios!$D$4 | D14: =Cohort!D13 | E14: =Cohort!E13*Scenarios!$D$4 | F14: =Cohort!F13*Scenarios!$D$4 | G14: =Cohort!G13*Scenarios!$D$4 | H14: =C14*Scenarios!$D$5 | I14: =L13*(1-D14)+H14 | J14: =MIN(Inputs!$C$25,I14) | K14: =IF(A14<Inputs!$C$17,0,Inputs!$C$16*(I14-J14)) | L14: =I14-J14-K14 | M14: =K14*Inputs!$C$18 | N14: =Q13*(1-D14)+H14 | O14: =IF(A14<Inputs!$C$17,MIN(Inputs!$C$25,N14),0) | P14: =IF(A14<Inputs!$C$17,0,MIN(Inputs!$C$25,N14)+Inputs!$C$16*(N14-MIN(Inputs!$C$25,N14))) | Q14: =N14-O14-P14 | R14: =P14*Inputs!$C$18 | S14: =Cohort!H13 | T14: =B14/S14
A15: 2012 | B15: =Cohort!B14*Scenarios!$D$4 | C15: =Cohort!C14*Scenarios!$D$4 | D15: =Cohort!D14 | E15: =Cohort!E14*Scenarios!$D$4 | F15: =Cohort!F14*Scenarios!$D$4 | G15: =Cohort!G14*Scenarios!$D$4 | H15: =C15*Scenarios!$D$5 | I15: =L14*(1-D15)+H15 | J15: =MIN(Inputs!$C$25,I15) | K15: =IF(A15<Inputs!$C$17,0,Inputs!$C$16*(I15-J15)) | L15: =I15-J15-K15 | M15: =K15*Inputs!$C$18 | N15: =Q14*(1-D15)+H15 | O15: =IF(A15<Inputs!$C$17,MIN(Inputs!$C$25,N15),0) | P15: =IF(A15<Inputs!$C$17,0,MIN(Inputs!$C$25,N15)+Inputs!$C$16*(N15-MIN(Inputs!$C$25,N15))) | Q15: =N15-O15-P15 | R15: =P15*Inputs!$C$18 | S15: =Cohort!H14 | T15: =B15/S15
... A48: 2045 | B48: =Cohort!B47*Scenarios!$D$4 | C48: =Cohort!C47*Scenarios!$D$4 | D48: =Cohort!D47 | E48: =Cohort!E47*Scenarios!$D$4 | F48: =Cohort!F47*Scenarios!$D$4 | G48: =Cohort!G47*Scenarios!$D$4 | H48: =C48*Scenarios!$D$5 | I48: =L47*(1-D48)+H48 | J48: =MIN(Inputs!$C$25,I48) | K48: =IF(A48<Inputs!$C$17,0,Inputs!$C$16*(I48-J48)) | L48: =I48-J48-K48 | M48: =K48*Inputs!$C$18 | N48: =Q47*(1-D48)+H48 | O48: =IF(A48<Inputs!$C$17,MIN(Inputs!$C$25,N48),0) | P48: =IF(A48<Inputs!$C$17,0,MIN(Inputs!$C$25,N48)+Inputs!$C$16*(N48-MIN(Inputs!$C$25,N48))) | Q48: =N48-O48-P48 | R48: =P48*Inputs!$C$18 | S48: =Cohort!H47 | T48: =B48/S48

Sheet Flow 10%
A1: Eligibility case 10%. Eligible = Cohort × g; funnel inflow = newly eligible × P. Pre-launch DBS = MIN(DBS under cap, pool). After launch: A keeps DBS and the one-time therapy draws kf of the backlog; B replaces DBS (DBS-equivalent volume + kf of backlog). Rows before FY2026 grouped.
A2: FY | B2: Eligible stock | C2: Newly eligible | D2: Exit μ | E2: Deaths | F2: Dementia | G2: Aged past cap | H2: Funnel inflow (×P) | I2: A: pool available | J2: A: DBS | K2: A: one-time | L2: A: backlog end | M2: A: $M | N2: B: pool available | O2: B: DBS | P2: B: one-time | Q2: B: backlog end | R2: B: $M | S2: PD prevalent | T2: Eligible % of PD
A3: 2000 | L3: 0 | Q3: 0
A4: 2001 | B4: =Cohort!B3*Scenarios!$E$4 | C4: =Cohort!C3*Scenarios!$E$4 | D4: =Cohort!D3 | E4: =Cohort!E3*Scenarios!$E$4 | F4: =Cohort!F3*Scenarios!$E$4 | G4: =Cohort!G3*Scenarios!$E$4 | H4: =C4*Scenarios!$E$5 | I4: =L3*(1-D4)+H4 | J4: =MIN(Inputs!$C$25,I4) | K4: =IF(A4<Inputs!$C$17,0,Inputs!$C$16*(I4-J4)) | L4: =I4-J4-K4 | M4: =K4*Inputs!$C$18 | N4: =Q3*(1-D4)+H4 | O4: =IF(A4<Inputs!$C$17,MIN(Inputs!$C$25,N4),0) | P4: =IF(A4<Inputs!$C$17,0,MIN(Inputs!$C$25,N4)+Inputs!$C$16*(N4-MIN(Inputs!$C$25,N4))) | Q4: =N4-O4-P4 | R4: =P4*Inputs!$C$18 | S4: =Cohort!H3 | T4: =B4/S4
A5: 2002 | B5: =Cohort!B4*Scenarios!$E$4 | C5: =Cohort!C4*Scenarios!$E$4 | D5: =Cohort!D4 | E5: =Cohort!E4*Scenarios!$E$4 | F5: =Cohort!F4*Scenarios!$E$4 | G5: =Cohort!G4*Scenarios!$E$4 | H5: =C5*Scenarios!$E$5 | I5: =L4*(1-D5)+H5 | J5: =MIN(Inputs!$C$25,I5) | K5: =IF(A5<Inputs!$C$17,0,Inputs!$C$16*(I5-J5)) | L5: =I5-J5-K5 | M5: =K5*Inputs!$C$18 | N5: =Q4*(1-D5)+H5 | O5: =IF(A5<Inputs!$C$17,MIN(Inputs!$C$25,N5),0) | P5: =IF(A5<Inputs!$C$17,0,MIN(Inputs!$C$25,N5)+Inputs!$C$16*(N5-MIN(Inputs!$C$25,N5))) | Q5: =N5-O5-P5 | R5: =P5*Inputs!$C$18 | S5: =Cohort!H4 | T5: =B5/S5
A6: 2003 | B6: =Cohort!B5*Scenarios!$E$4 | C6: =Cohort!C5*Scenarios!$E$4 | D6: =Cohort!D5 | E6: =Cohort!E5*Scenarios!$E$4 | F6: =Cohort!F5*Scenarios!$E$4 | G6: =Cohort!G5*Scenarios!$E$4 | H6: =C6*Scenarios!$E$5 | I6: =L5*(1-D6)+H6 | J6: =MIN(Inputs!$C$25,I6) | K6: =IF(A6<Inputs!$C$17,0,Inputs!$C$16*(I6-J6)) | L6: =I6-J6-K6 | M6: =K6*Inputs!$C$18 | N6: =Q5*(1-D6)+H6 | O6: =IF(A6<Inputs!$C$17,MIN(Inputs!$C$25,N6),0) | P6: =IF(A6<Inputs!$C$17,0,MIN(Inputs!$C$25,N6)+Inputs!$C$16*(N6-MIN(Inputs!$C$25,N6))) | Q6: =N6-O6-P6 | R6: =P6*Inputs!$C$18 | S6: =Cohort!H5 | T6: =B6/S6
A7: 2004 | B7: =Cohort!B6*Scenarios!$E$4 | C7: =Cohort!C6*Scenarios!$E$4 | D7: =Cohort!D6 | E7: =Cohort!E6*Scenarios!$E$4 | F7: =Cohort!F6*Scenarios!$E$4 | G7: =Cohort!G6*Scenarios!$E$4 | H7: =C7*Scenarios!$E$5 | I7: =L6*(1-D7)+H7 | J7: =MIN(Inputs!$C$25,I7) | K7: =IF(A7<Inputs!$C$17,0,Inputs!$C$16*(I7-J7)) | L7: =I7-J7-K7 | M7: =K7*Inputs!$C$18 | N7: =Q6*(1-D7)+H7 | O7: =IF(A7<Inputs!$C$17,MIN(Inputs!$C$25,N7),0) | P7: =IF(A7<Inputs!$C$17,0,MIN(Inputs!$C$25,N7)+Inputs!$C$16*(N7-MIN(Inputs!$C$25,N7))) | Q7: =N7-O7-P7 | R7: =P7*Inputs!$C$18 | S7: =Cohort!H6 | T7: =B7/S7
A8: 2005 | B8: =Cohort!B7*Scenarios!$E$4 | C8: =Cohort!C7*Scenarios!$E$4 | D8: =Cohort!D7 | E8: =Cohort!E7*Scenarios!$E$4 | F8: =Cohort!F7*Scenarios!$E$4 | G8: =Cohort!G7*Scenarios!$E$4 | H8: =C8*Scenarios!$E$5 | I8: =L7*(1-D8)+H8 | J8: =MIN(Inputs!$C$25,I8) | K8: =IF(A8<Inputs!$C$17,0,Inputs!$C$16*(I8-J8)) | L8: =I8-J8-K8 | M8: =K8*Inputs!$C$18 | N8: =Q7*(1-D8)+H8 | O8: =IF(A8<Inputs!$C$17,MIN(Inputs!$C$25,N8),0) | P8: =IF(A8<Inputs!$C$17,0,MIN(Inputs!$C$25,N8)+Inputs!$C$16*(N8-MIN(Inputs!$C$25,N8))) | Q8: =N8-O8-P8 | R8: =P8*Inputs!$C$18 | S8: =Cohort!H7 | T8: =B8/S8
A9: 2006 | B9: =Cohort!B8*Scenarios!$E$4 | C9: =Cohort!C8*Scenarios!$E$4 | D9: =Cohort!D8 | E9: =Cohort!E8*Scenarios!$E$4 | F9: =Cohort!F8*Scenarios!$E$4 | G9: =Cohort!G8*Scenarios!$E$4 | H9: =C9*Scenarios!$E$5 | I9: =L8*(1-D9)+H9 | J9: =MIN(Inputs!$C$25,I9) | K9: =IF(A9<Inputs!$C$17,0,Inputs!$C$16*(I9-J9)) | L9: =I9-J9-K9 | M9: =K9*Inputs!$C$18 | N9: =Q8*(1-D9)+H9 | O9: =IF(A9<Inputs!$C$17,MIN(Inputs!$C$25,N9),0) | P9: =IF(A9<Inputs!$C$17,0,MIN(Inputs!$C$25,N9)+Inputs!$C$16*(N9-MIN(Inputs!$C$25,N9))) | Q9: =N9-O9-P9 | R9: =P9*Inputs!$C$18 | S9: =Cohort!H8 | T9: =B9/S9
A10: 2007 | B10: =Cohort!B9*Scenarios!$E$4 | C10: =Cohort!C9*Scenarios!$E$4 | D10: =Cohort!D9 | E10: =Cohort!E9*Scenarios!$E$4 | F10: =Cohort!F9*Scenarios!$E$4 | G10: =Cohort!G9*Scenarios!$E$4 | H10: =C10*Scenarios!$E$5 | I10: =L9*(1-D10)+H10 | J10: =MIN(Inputs!$C$25,I10) | K10: =IF(A10<Inputs!$C$17,0,Inputs!$C$16*(I10-J10)) | L10: =I10-J10-K10 | M10: =K10*Inputs!$C$18 | N10: =Q9*(1-D10)+H10 | O10: =IF(A10<Inputs!$C$17,MIN(Inputs!$C$25,N10),0) | P10: =IF(A10<Inputs!$C$17,0,MIN(Inputs!$C$25,N10)+Inputs!$C$16*(N10-MIN(Inputs!$C$25,N10))) | Q10: =N10-O10-P10 | R10: =P10*Inputs!$C$18 | S10: =Cohort!H9 | T10: =B10/S10
A11: 2008 | B11: =Cohort!B10*Scenarios!$E$4 | C11: =Cohort!C10*Scenarios!$E$4 | D11: =Cohort!D10 | E11: =Cohort!E10*Scenarios!$E$4 | F11: =Cohort!F10*Scenarios!$E$4 | G11: =Cohort!G10*Scenarios!$E$4 | H11: =C11*Scenarios!$E$5 | I11: =L10*(1-D11)+H11 | J11: =MIN(Inputs!$C$25,I11) | K11: =IF(A11<Inputs!$C$17,0,Inputs!$C$16*(I11-J11)) | L11: =I11-J11-K11 | M11: =K11*Inputs!$C$18 | N11: =Q10*(1-D11)+H11 | O11: =IF(A11<Inputs!$C$17,MIN(Inputs!$C$25,N11),0) | P11: =IF(A11<Inputs!$C$17,0,MIN(Inputs!$C$25,N11)+Inputs!$C$16*(N11-MIN(Inputs!$C$25,N11))) | Q11: =N11-O11-P11 | R11: =P11*Inputs!$C$18 | S11: =Cohort!H10 | T11: =B11/S11
A12: 2009 | B12: =Cohort!B11*Scenarios!$E$4 | C12: =Cohort!C11*Scenarios!$E$4 | D12: =Cohort!D11 | E12: =Cohort!E11*Scenarios!$E$4 | F12: =Cohort!F11*Scenarios!$E$4 | G12: =Cohort!G11*Scenarios!$E$4 | H12: =C12*Scenarios!$E$5 | I12: =L11*(1-D12)+H12 | J12: =MIN(Inputs!$C$25,I12) | K12: =IF(A12<Inputs!$C$17,0,Inputs!$C$16*(I12-J12)) | L12: =I12-J12-K12 | M12: =K12*Inputs!$C$18 | N12: =Q11*(1-D12)+H12 | O12: =IF(A12<Inputs!$C$17,MIN(Inputs!$C$25,N12),0) | P12: =IF(A12<Inputs!$C$17,0,MIN(Inputs!$C$25,N12)+Inputs!$C$16*(N12-MIN(Inputs!$C$25,N12))) | Q12: =N12-O12-P12 | R12: =P12*Inputs!$C$18 | S12: =Cohort!H11 | T12: =B12/S12
A13: 2010 | B13: =Cohort!B12*Scenarios!$E$4 | C13: =Cohort!C12*Scenarios!$E$4 | D13: =Cohort!D12 | E13: =Cohort!E12*Scenarios!$E$4 | F13: =Cohort!F12*Scenarios!$E$4 | G13: =Cohort!G12*Scenarios!$E$4 | H13: =C13*Scenarios!$E$5 | I13: =L12*(1-D13)+H13 | J13: =MIN(Inputs!$C$25,I13) | K13: =IF(A13<Inputs!$C$17,0,Inputs!$C$16*(I13-J13)) | L13: =I13-J13-K13 | M13: =K13*Inputs!$C$18 | N13: =Q12*(1-D13)+H13 | O13: =IF(A13<Inputs!$C$17,MIN(Inputs!$C$25,N13),0) | P13: =IF(A13<Inputs!$C$17,0,MIN(Inputs!$C$25,N13)+Inputs!$C$16*(N13-MIN(Inputs!$C$25,N13))) | Q13: =N13-O13-P13 | R13: =P13*Inputs!$C$18 | S13: =Cohort!H12 | T13: =B13/S13
A14: 2011 | B14: =Cohort!B13*Scenarios!$E$4 | C14: =Cohort!C13*Scenarios!$E$4 | D14: =Cohort!D13 | E14: =Cohort!E13*Scenarios!$E$4 | F14: =Cohort!F13*Scenarios!$E$4 | G14: =Cohort!G13*Scenarios!$E$4 | H14: =C14*Scenarios!$E$5 | I14: =L13*(1-D14)+H14 | J14: =MIN(Inputs!$C$25,I14) | K14: =IF(A14<Inputs!$C$17,0,Inputs!$C$16*(I14-J14)) | L14: =I14-J14-K14 | M14: =K14*Inputs!$C$18 | N14: =Q13*(1-D14)+H14 | O14: =IF(A14<Inputs!$C$17,MIN(Inputs!$C$25,N14),0) | P14: =IF(A14<Inputs!$C$17,0,MIN(Inputs!$C$25,N14)+Inputs!$C$16*(N14-MIN(Inputs!$C$25,N14))) | Q14: =N14-O14-P14 | R14: =P14*Inputs!$C$18 | S14: =Cohort!H13 | T14: =B14/S14
A15: 2012 | B15: =Cohort!B14*Scenarios!$E$4 | C15: =Cohort!C14*Scenarios!$E$4 | D15: =Cohort!D14 | E15: =Cohort!E14*Scenarios!$E$4 | F15: =Cohort!F14*Scenarios!$E$4 | G15: =Cohort!G14*Scenarios!$E$4 | H15: =C15*Scenarios!$E$5 | I15: =L14*(1-D15)+H15 | J15: =MIN(Inputs!$C$25,I15) | K15: =IF(A15<Inputs!$C$17,0,Inputs!$C$16*(I15-J15)) | L15: =I15-J15-K15 | M15: =K15*Inputs!$C$18 | N15: =Q14*(1-D15)+H15 | O15: =IF(A15<Inputs!$C$17,MIN(Inputs!$C$25,N15),0) | P15: =IF(A15<Inputs!$C$17,0,MIN(Inputs!$C$25,N15)+Inputs!$C$16*(N15-MIN(Inputs!$C$25,N15))) | Q15: =N15-O15-P15 | R15: =P15*Inputs!$C$18 | S15: =Cohort!H14 | T15: =B15/S15
... A48: 2045 | B48: =Cohort!B47*Scenarios!$E$4 | C48: =Cohort!C47*Scenarios!$E$4 | D48: =Cohort!D47 | E48: =Cohort!E47*Scenarios!$E$4 | F48: =Cohort!F47*Scenarios!$E$4 | G48: =Cohort!G47*Scenarios!$E$4 | H48: =C48*Scenarios!$E$5 | I48: =L47*(1-D48)+H48 | J48: =MIN(Inputs!$C$25,I48) | K48: =IF(A48<Inputs!$C$17,0,Inputs!$C$16*(I48-J48)) | L48: =I48-J48-K48 | M48: =K48*Inputs!$C$18 | N48: =Q47*(1-D48)+H48 | O48: =IF(A48<Inputs!$C$17,MIN(Inputs!$C$25,N48),0) | P48: =IF(A48<Inputs!$C$17,0,MIN(Inputs!$C$25,N48)+Inputs!$C$16*(N48-MIN(Inputs!$C$25,N48))) | Q48: =N48-O48-P48 | R48: =P48*Inputs!$C$18 | S48: =Cohort!H47 | T48: =B48/S48

Sheet Flow 15%
A1: Eligibility case 15%. Eligible = Cohort × g; funnel inflow = newly eligible × P. Pre-launch DBS = MIN(DBS under cap, pool). After launch: A keeps DBS and the one-time therapy draws kf of the backlog; B replaces DBS (DBS-equivalent volume + kf of backlog). Rows before FY2026 grouped.
A2: FY | B2: Eligible stock | C2: Newly eligible | D2: Exit μ | E2: Deaths | F2: Dementia | G2: Aged past cap | H2: Funnel inflow (×P) | I2: A: pool available | J2: A: DBS | K2: A: one-time | L2: A: backlog end | M2: A: $M | N2: B: pool available | O2: B: DBS | P2: B: one-time | Q2: B: backlog end | R2: B: $M | S2: PD prevalent | T2: Eligible % of PD
A3: 2000 | L3: 0 | Q3: 0
A4: 2001 | B4: =Cohort!B3*Scenarios!$F$4 | C4: =Cohort!C3*Scenarios!$F$4 | D4: =Cohort!D3 | E4: =Cohort!E3*Scenarios!$F$4 | F4: =Cohort!F3*Scenarios!$F$4 | G4: =Cohort!G3*Scenarios!$F$4 | H4: =C4*Scenarios!$F$5 | I4: =L3*(1-D4)+H4 | J4: =MIN(Inputs!$C$25,I4) | K4: =IF(A4<Inputs!$C$17,0,Inputs!$C$16*(I4-J4)) | L4: =I4-J4-K4 | M4: =K4*Inputs!$C$18 | N4: =Q3*(1-D4)+H4 | O4: =IF(A4<Inputs!$C$17,MIN(Inputs!$C$25,N4),0) | P4: =IF(A4<Inputs!$C$17,0,MIN(Inputs!$C$25,N4)+Inputs!$C$16*(N4-MIN(Inputs!$C$25,N4))) | Q4: =N4-O4-P4 | R4: =P4*Inputs!$C$18 | S4: =Cohort!H3 | T4: =B4/S4
A5: 2002 | B5: =Cohort!B4*Scenarios!$F$4 | C5: =Cohort!C4*Scenarios!$F$4 | D5: =Cohort!D4 | E5: =Cohort!E4*Scenarios!$F$4 | F5: =Cohort!F4*Scenarios!$F$4 | G5: =Cohort!G4*Scenarios!$F$4 | H5: =C5*Scenarios!$F$5 | I5: =L4*(1-D5)+H5 | J5: =MIN(Inputs!$C$25,I5) | K5: =IF(A5<Inputs!$C$17,0,Inputs!$C$16*(I5-J5)) | L5: =I5-J5-K5 | M5: =K5*Inputs!$C$18 | N5: =Q4*(1-D5)+H5 | O5: =IF(A5<Inputs!$C$17,MIN(Inputs!$C$25,N5),0) | P5: =IF(A5<Inputs!$C$17,0,MIN(Inputs!$C$25,N5)+Inputs!$C$16*(N5-MIN(Inputs!$C$25,N5))) | Q5: =N5-O5-P5 | R5: =P5*Inputs!$C$18 | S5: =Cohort!H4 | T5: =B5/S5
A6: 2003 | B6: =Cohort!B5*Scenarios!$F$4 | C6: =Cohort!C5*Scenarios!$F$4 | D6: =Cohort!D5 | E6: =Cohort!E5*Scenarios!$F$4 | F6: =Cohort!F5*Scenarios!$F$4 | G6: =Cohort!G5*Scenarios!$F$4 | H6: =C6*Scenarios!$F$5 | I6: =L5*(1-D6)+H6 | J6: =MIN(Inputs!$C$25,I6) | K6: =IF(A6<Inputs!$C$17,0,Inputs!$C$16*(I6-J6)) | L6: =I6-J6-K6 | M6: =K6*Inputs!$C$18 | N6: =Q5*(1-D6)+H6 | O6: =IF(A6<Inputs!$C$17,MIN(Inputs!$C$25,N6),0) | P6: =IF(A6<Inputs!$C$17,0,MIN(Inputs!$C$25,N6)+Inputs!$C$16*(N6-MIN(Inputs!$C$25,N6))) | Q6: =N6-O6-P6 | R6: =P6*Inputs!$C$18 | S6: =Cohort!H5 | T6: =B6/S6
A7: 2004 | B7: =Cohort!B6*Scenarios!$F$4 | C7: =Cohort!C6*Scenarios!$F$4 | D7: =Cohort!D6 | E7: =Cohort!E6*Scenarios!$F$4 | F7: =Cohort!F6*Scenarios!$F$4 | G7: =Cohort!G6*Scenarios!$F$4 | H7: =C7*Scenarios!$F$5 | I7: =L6*(1-D7)+H7 | J7: =MIN(Inputs!$C$25,I7) | K7: =IF(A7<Inputs!$C$17,0,Inputs!$C$16*(I7-J7)) | L7: =I7-J7-K7 | M7: =K7*Inputs!$C$18 | N7: =Q6*(1-D7)+H7 | O7: =IF(A7<Inputs!$C$17,MIN(Inputs!$C$25,N7),0) | P7: =IF(A7<Inputs!$C$17,0,MIN(Inputs!$C$25,N7)+Inputs!$C$16*(N7-MIN(Inputs!$C$25,N7))) | Q7: =N7-O7-P7 | R7: =P7*Inputs!$C$18 | S7: =Cohort!H6 | T7: =B7/S7
A8: 2005 | B8: =Cohort!B7*Scenarios!$F$4 | C8: =Cohort!C7*Scenarios!$F$4 | D8: =Cohort!D7 | E8: =Cohort!E7*Scenarios!$F$4 | F8: =Cohort!F7*Scenarios!$F$4 | G8: =Cohort!G7*Scenarios!$F$4 | H8: =C8*Scenarios!$F$5 | I8: =L7*(1-D8)+H8 | J8: =MIN(Inputs!$C$25,I8) | K8: =IF(A8<Inputs!$C$17,0,Inputs!$C$16*(I8-J8)) | L8: =I8-J8-K8 | M8: =K8*Inputs!$C$18 | N8: =Q7*(1-D8)+H8 | O8: =IF(A8<Inputs!$C$17,MIN(Inputs!$C$25,N8),0) | P8: =IF(A8<Inputs!$C$17,0,MIN(Inputs!$C$25,N8)+Inputs!$C$16*(N8-MIN(Inputs!$C$25,N8))) | Q8: =N8-O8-P8 | R8: =P8*Inputs!$C$18 | S8: =Cohort!H7 | T8: =B8/S8
A9: 2006 | B9: =Cohort!B8*Scenarios!$F$4 | C9: =Cohort!C8*Scenarios!$F$4 | D9: =Cohort!D8 | E9: =Cohort!E8*Scenarios!$F$4 | F9: =Cohort!F8*Scenarios!$F$4 | G9: =Cohort!G8*Scenarios!$F$4 | H9: =C9*Scenarios!$F$5 | I9: =L8*(1-D9)+H9 | J9: =MIN(Inputs!$C$25,I9) | K9: =IF(A9<Inputs!$C$17,0,Inputs!$C$16*(I9-J9)) | L9: =I9-J9-K9 | M9: =K9*Inputs!$C$18 | N9: =Q8*(1-D9)+H9 | O9: =IF(A9<Inputs!$C$17,MIN(Inputs!$C$25,N9),0) | P9: =IF(A9<Inputs!$C$17,0,MIN(Inputs!$C$25,N9)+Inputs!$C$16*(N9-MIN(Inputs!$C$25,N9))) | Q9: =N9-O9-P9 | R9: =P9*Inputs!$C$18 | S9: =Cohort!H8 | T9: =B9/S9
A10: 2007 | B10: =Cohort!B9*Scenarios!$F$4 | C10: =Cohort!C9*Scenarios!$F$4 | D10: =Cohort!D9 | E10: =Cohort!E9*Scenarios!$F$4 | F10: =Cohort!F9*Scenarios!$F$4 | G10: =Cohort!G9*Scenarios!$F$4 | H10: =C10*Scenarios!$F$5 | I10: =L9*(1-D10)+H10 | J10: =MIN(Inputs!$C$25,I10) | K10: =IF(A10<Inputs!$C$17,0,Inputs!$C$16*(I10-J10)) | L10: =I10-J10-K10 | M10: =K10*Inputs!$C$18 | N10: =Q9*(1-D10)+H10 | O10: =IF(A10<Inputs!$C$17,MIN(Inputs!$C$25,N10),0) | P10: =IF(A10<Inputs!$C$17,0,MIN(Inputs!$C$25,N10)+Inputs!$C$16*(N10-MIN(Inputs!$C$25,N10))) | Q10: =N10-O10-P10 | R10: =P10*Inputs!$C$18 | S10: =Cohort!H9 | T10: =B10/S10
A11: 2008 | B11: =Cohort!B10*Scenarios!$F$4 | C11: =Cohort!C10*Scenarios!$F$4 | D11: =Cohort!D10 | E11: =Cohort!E10*Scenarios!$F$4 | F11: =Cohort!F10*Scenarios!$F$4 | G11: =Cohort!G10*Scenarios!$F$4 | H11: =C11*Scenarios!$F$5 | I11: =L10*(1-D11)+H11 | J11: =MIN(Inputs!$C$25,I11) | K11: =IF(A11<Inputs!$C$17,0,Inputs!$C$16*(I11-J11)) | L11: =I11-J11-K11 | M11: =K11*Inputs!$C$18 | N11: =Q10*(1-D11)+H11 | O11: =IF(A11<Inputs!$C$17,MIN(Inputs!$C$25,N11),0) | P11: =IF(A11<Inputs!$C$17,0,MIN(Inputs!$C$25,N11)+Inputs!$C$16*(N11-MIN(Inputs!$C$25,N11))) | Q11: =N11-O11-P11 | R11: =P11*Inputs!$C$18 | S11: =Cohort!H10 | T11: =B11/S11
A12: 2009 | B12: =Cohort!B11*Scenarios!$F$4 | C12: =Cohort!C11*Scenarios!$F$4 | D12: =Cohort!D11 | E12: =Cohort!E11*Scenarios!$F$4 | F12: =Cohort!F11*Scenarios!$F$4 | G12: =Cohort!G11*Scenarios!$F$4 | H12: =C12*Scenarios!$F$5 | I12: =L11*(1-D12)+H12 | J12: =MIN(Inputs!$C$25,I12) | K12: =IF(A12<Inputs!$C$17,0,Inputs!$C$16*(I12-J12)) | L12: =I12-J12-K12 | M12: =K12*Inputs!$C$18 | N12: =Q11*(1-D12)+H12 | O12: =IF(A12<Inputs!$C$17,MIN(Inputs!$C$25,N12),0) | P12: =IF(A12<Inputs!$C$17,0,MIN(Inputs!$C$25,N12)+Inputs!$C$16*(N12-MIN(Inputs!$C$25,N12))) | Q12: =N12-O12-P12 | R12: =P12*Inputs!$C$18 | S12: =Cohort!H11 | T12: =B12/S12
A13: 2010 | B13: =Cohort!B12*Scenarios!$F$4 | C13: =Cohort!C12*Scenarios!$F$4 | D13: =Cohort!D12 | E13: =Cohort!E12*Scenarios!$F$4 | F13: =Cohort!F12*Scenarios!$F$4 | G13: =Cohort!G12*Scenarios!$F$4 | H13: =C13*Scenarios!$F$5 | I13: =L12*(1-D13)+H13 | J13: =MIN(Inputs!$C$25,I13) | K13: =IF(A13<Inputs!$C$17,0,Inputs!$C$16*(I13-J13)) | L13: =I13-J13-K13 | M13: =K13*Inputs!$C$18 | N13: =Q12*(1-D13)+H13 | O13: =IF(A13<Inputs!$C$17,MIN(Inputs!$C$25,N13),0) | P13: =IF(A13<Inputs!$C$17,0,MIN(Inputs!$C$25,N13)+Inputs!$C$16*(N13-MIN(Inputs!$C$25,N13))) | Q13: =N13-O13-P13 | R13: =P13*Inputs!$C$18 | S13: =Cohort!H12 | T13: =B13/S13
A14: 2011 | B14: =Cohort!B13*Scenarios!$F$4 | C14: =Cohort!C13*Scenarios!$F$4 | D14: =Cohort!D13 | E14: =Cohort!E13*Scenarios!$F$4 | F14: =Cohort!F13*Scenarios!$F$4 | G14: =Cohort!G13*Scenarios!$F$4 | H14: =C14*Scenarios!$F$5 | I14: =L13*(1-D14)+H14 | J14: =MIN(Inputs!$C$25,I14) | K14: =IF(A14<Inputs!$C$17,0,Inputs!$C$16*(I14-J14)) | L14: =I14-J14-K14 | M14: =K14*Inputs!$C$18 | N14: =Q13*(1-D14)+H14 | O14: =IF(A14<Inputs!$C$17,MIN(Inputs!$C$25,N14),0) | P14: =IF(A14<Inputs!$C$17,0,MIN(Inputs!$C$25,N14)+Inputs!$C$16*(N14-MIN(Inputs!$C$25,N14))) | Q14: =N14-O14-P14 | R14: =P14*Inputs!$C$18 | S14: =Cohort!H13 | T14: =B14/S14
A15: 2012 | B15: =Cohort!B14*Scenarios!$F$4 | C15: =Cohort!C14*Scenarios!$F$4 | D15: =Cohort!D14 | E15: =Cohort!E14*Scenarios!$F$4 | F15: =Cohort!F14*Scenarios!$F$4 | G15: =Cohort!G14*Scenarios!$F$4 | H15: =C15*Scenarios!$F$5 | I15: =L14*(1-D15)+H15 | J15: =MIN(Inputs!$C$25,I15) | K15: =IF(A15<Inputs!$C$17,0,Inputs!$C$16*(I15-J15)) | L15: =I15-J15-K15 | M15: =K15*Inputs!$C$18 | N15: =Q14*(1-D15)+H15 | O15: =IF(A15<Inputs!$C$17,MIN(Inputs!$C$25,N15),0) | P15: =IF(A15<Inputs!$C$17,0,MIN(Inputs!$C$25,N15)+Inputs!$C$16*(N15-MIN(Inputs!$C$25,N15))) | Q15: =N15-O15-P15 | R15: =P15*Inputs!$C$18 | S15: =Cohort!H14 | T15: =B15/S15
... A48: 2045 | B48: =Cohort!B47*Scenarios!$F$4 | C48: =Cohort!C47*Scenarios!$F$4 | D48: =Cohort!D47 | E48: =Cohort!E47*Scenarios!$F$4 | F48: =Cohort!F47*Scenarios!$F$4 | G48: =Cohort!G47*Scenarios!$F$4 | H48: =C48*Scenarios!$F$5 | I48: =L47*(1-D48)+H48 | J48: =MIN(Inputs!$C$25,I48) | K48: =IF(A48<Inputs!$C$17,0,Inputs!$C$16*(I48-J48)) | L48: =I48-J48-K48 | M48: =K48*Inputs!$C$18 | N48: =Q47*(1-D48)+H48 | O48: =IF(A48<Inputs!$C$17,MIN(Inputs!$C$25,N48),0) | P48: =IF(A48<Inputs!$C$17,0,MIN(Inputs!$C$25,N48)+Inputs!$C$16*(N48-MIN(Inputs!$C$25,N48))) | Q48: =N48-O48-P48 | R48: =P48*Inputs!$C$18 | S48: =Cohort!H47 | T48: =B48/S48

Sheet Age-band funnel
A1: FY2026 by age band, central 8% case. B–D from the cohort model; E onward live.
A2: Age band | B2: PD prevalent | C2: Alive, no dementia, under cap, ≥4 yrs | D2: … with motor complications | E2: Eligible, published screens (× dx × S1 × S2) | F2: Eligible, central (× g) | G2: Funnel (× P) | H2: Eligible % of band PD
A3: <50 | B3: 8795.7576 | C3: 2484.8578 | D3: 1163.7894 | E3: =D3*Inputs!$C$8*Inputs!$C$10*Inputs!$C$11 | F3: =E3*Scenarios!$D$4 | G3: =F3*Scenarios!$D$5 | H3: =IF(B3>0,F3/B3,0)
A4: 50–59 | B4: 39537.51 | C4: 14885.66 | D4: 8972.3367 | E4: =D4*Inputs!$C$8*Inputs!$C$10*Inputs!$C$11 | F4: =E4*Scenarios!$D$4 | G4: =F4*Scenarios!$D$5 | H4: =IF(B4>0,F4/B4,0)
A5: 60–64 | B5: 56741.672 | C5: 16502.459 | D5: 10677.234 | E5: =D5*Inputs!$C$8*Inputs!$C$10*Inputs!$C$11 | F5: =E5*Scenarios!$D$4 | G5: =F5*Scenarios!$D$5 | H5: =IF(B5>0,F5/B5,0)
A6: 65–69 | B6: 92863.421 | C6: 37802.194 | D6: 22397.381 | E6: =D6*Inputs!$C$8*Inputs!$C$10*Inputs!$C$11 | F6: =E6*Scenarios!$D$4 | G6: =F6*Scenarios!$D$5 | H6: =IF(B6>0,F6/B6,0)
A7: 70–74 | B7: 154796.98 | C7: 52072.837 | D7: 34631.995 | E7: =D7*Inputs!$C$8*Inputs!$C$10*Inputs!$C$11 | F7: =E7*Scenarios!$D$4 | G7: =F7*Scenarios!$D$5 | H7: =IF(B7>0,F7/B7,0)
A8: 75–79 | B8: 197041.32 | C8: 0 | D8: 0 | E8: =D8*Inputs!$C$8*Inputs!$C$10*Inputs!$C$11 | F8: =E8*Scenarios!$D$4 | G8: =F8*Scenarios!$D$5 | H8: =IF(B8>0,F8/B8,0)
A9: 80+ | B9: 373046.17 | C9: 0 | D9: 0 | E9: =D9*Inputs!$C$8*Inputs!$C$10*Inputs!$C$11 | F9: =E9*Scenarios!$D$4 | G9: =F9*Scenarios!$D$5 | H9: =IF(B9>0,F9/B9,0)
A10: Total | B10: =SUM(B3:B9) | C10: =SUM(C3:C9) | D10: =SUM(D3:D9) | E10: =SUM(E3:E9) | F10: =SUM(F3:F9) | G10: =SUM(G3:G9) | H10: =F10/B10

Sheet Sensitivity
A1: One-at-a-time sensitivity, central 8% case (values from pd_pool_model.py). FY2040 class one-time demand, patients; P = calibrated product.
A2: Input | B2: First value | C2: Second value | D2: A first | E2: A second | F2: B first | G2: B second | H2: P first | I2: P second
A3: Base | D3: 1968.1909 | F3: 5359.6909 | H3: 0.29983537
A4: Eligibility share (5% / 15%) | B4: 0.05 | C4: 0.15 | D4: 1968.1909 | E4: 1968.1909 | F4: 5359.6909 | G4: 5359.6909 | H4: 0.47973658 | I4: 0.15991219
A5: DBS under-cap target, FY2019 (3.0k / 4.5k) | B5: 0.75 | C5: 1.1278195 | D5: 1736.639 | E5: 2611.4872 | F5: 4729.139 | G5: 7111.4872 | H5: 0.26456062 | I5: 0.39783551
A6: Backlog draw-down after launch (25% / 100%) | B6: 0.25 | C6: 1 | D6: 1451.5869 | E6: 2389.6764 | F6: 4843.0869 | G6: 5781.1764 | H6: 0.29983537 | I6: 0.29983537
A7: Launch year (FY2031 / FY2028) | B7: 2031 | C7: 2028 | D7: 1968.6346 | E7: 1968.1492 | F7: 5360.1346 | G7: 5359.6492 | H7: 0.29983537 | I7: 0.29983537
A8: Age cap, shape only (70 / 80) | B8: 70 | C8: 80 | D8: 1936.9558 | E8: 1973.8445 | F8: 5328.4558 | G8: 5365.3445 | H8: 0.26976294 | I8: 0.30589249
A9: Mortality ratio (1.86 / 1.29) | B9: 1.86 | C9: 1.29 | D9: 1964.5352 | E9: 1970.6704 | F9: 5356.0352 | G9: 5362.1704 | H9: 0.32275157 | I9: 0.28292647
A10: Disease duration floor (5 / 0 yrs) | B10: 5 | C10: 0 | D10: 1974.25 | E10: 1965.1755 | F10: 5365.75 | G10: 5356.6755 | H10: 0.30633505 | I10: 0.29668817

Sheet Checks
A1: Check | B1: Target / published | C1: Model | D1: Note
A2: PD prevalent 2020 | B2: 930000 | C2: =Cohort!H22 | D2: Marras 2018 minimum [A19]
A3: PD prevalent 2030 | B3: 1238000 | C3: =Cohort!H32 | D3: Marras 2018 [A19]
A4: DBS under cap FY2019 vs central A: DBS | B4: =Inputs!$C$25 | C4: ='Flow 8%'!J22 | D4: Calibration identity
A5: Funnel inflow FY2019 (central) | B5: =Inputs!$C$25 | C5: ='Flow 8%'!H22 | D5: Equals DBS under cap by construction
A6: Ever-DBS share of incidence | B6: =Inputs!$C$22 | C6: =Scenarios!D11 | D6: Olmsted 4.8% all ages vs model under cap
A7: Central eligible % of PD FY2026 | B7: =Scenarios!D3 | C7: ='Age-band funnel'!H10 | D7: Should match
